<!-- Cartpole Model
    The state space is populated with joints in the order that they are
    defined in this file. The actuators also operate on joints.
    State-Space (name/joint/parameter):
        - cart      slider      position (m)
        - pole      hinge       angle (rad)
        - cart      slider      velocity (m/s)
        - pole      hinge       angular velocity (rad/s)
    Actuators (name/actuator/parameter):
        - cart      motor       force x (N)
-->
<mujoco model="cartpole">
  <compiler coordinate="local" inertiafromgeom="true"/>
  <!--  create a default joint type for cartpole model-->
  <default>
    <joint damping="0.2"/>
    <!--    two geoms can collide if the contype of one and the conaffinity of the other have a common bit set to 1 in their 32 bit -->
    <geom contype="3" conaffinity="3" friction="0 0 0" rgba="0.7 0.7 0 1"/>
  </default>
  <!--  time step is for internal simulation-->
  <option gravity="1e-5 0 -9.81" integrator="Euler" timestep="0.05"/>
  <!--  size of pre-allocated stack-->
  <size nstack="3000"/>
  <!--  start outermost environment or arena-->
  <worldbody>
    <!--    fixed camera glued to frame of static world body-->
    <camera name="rgb" mode="fixed" pos="0 4 0.0" euler="-90 0 180"/>
    <body name="cart" pos="0 0 0">
      <!-- place a joint at the center of the cart-pole for moving it l and r-->
      <joint name="slider" axis="1 0 0" limited="true" margin="0.01" pos="0 0 0" range="-100 100" type="slide"/>
      <geom pos="0 0 0" quat="0.707 0 0.707 0" rgba="1 1 1 1" size="0.01 0.01" mass="1." type="capsule" name="gcart"/>
      <body name="pole" pos="0 0 0">
        <joint axis="0 1 0" name="hinge" pos="0 0 0" type="hinge"/>
        <geom fromto="0 0 0 0 0 1.0" name="gpole" rgba="1 1 1 1" mass="1." size="0.1 0.5" type="capsule"/>
        <body name="mass" pos="0 0 1.">
            <geom size="0.2 0.2" mass="0" rgba="1 1 1 1" type="sphere" name="gmass" contype="3" conaffinity="3"/>
            <site name="tip" pos="0 0 0." size="0.01 0.01"/>
        </body>
      </body>
    </body>
  </worldbody>
  <actuator>
    <motor ctrllimited="true" ctrlrange="-1 1" gear="40" joint="slider" name="slide"/>
  </actuator>
</mujoco>
