<!-- Cartpole Model
    The state space is populated with joints in the order that they are
    defined in this file. The actuators also operate on joints.
    State-Space (name/joint/parameter):
        - cart      slider      position (m)
        - pole      hinge       angle (rad)
        - cart      slider      velocity (m/s)
        - pole      hinge       angular velocity (rad/s)
    Actuators (name/actuator/parameter):
        - cart      motor       force x (N)
-->
<mujoco model="cartpole">
  <compiler coordinate="local" inertiafromgeom="true"/>
  <!--  create defaults for joints in cartpole -->
  <default>
    <!-- larger damping values can make sim unstable-->
    <joint damping="0.2"/>
    <!--  two geoms can collide if the contype of one geom is compatible with the con-affinity of another geom and they
    have a common `1` in their 32b representations -->
    <!--    friction = (sliding, rolling, torsional)-->
    <geom contype="3" conaffinity="3" friction="0 0 0" rgba="0.7 0.7 0 1"/>
  </default>
  <!-- time step is physics time step, no separate control time-step -->
  <option gravity="1e-5 0 -9.81" integrator="Euler" timestep="0.05"/>
  <!--  initial size of allocated stack-->
  <size nstack="3000"/>
  <worldbody>
    <!-- Define a camera fixed relative to the static global world-body -->
    <camera name="rgb" mode="fixed" pos="0 4 0.0" euler="-90 0 180"/>
    <body name="cart" pos="0 0 0">
      <!--      the actuated joint which we call slider-->
      <!--      margin is distance below which contacts become active. Implements notion of soft contact -->
      <joint name="slider" axis="1 0 0" limited="true" margin="0.01" pos="0 0 0" range="-100 100" type="slide"/>
      <!--      small sized cart with orientation chosen such that we look at the planar object head on -->
      <geom name="gcart" type="capsule" pos="0 0 0" quat="0.707 0 0.707 0 " rgba="1 1 1 1" size="0.01 0.01" mass="1."/>
      <body name="pole" pos="0 0 0">
        <joint name="hinge" type="hinge" axis="0 1 0" pos="0 0 0"/>
        <geom name="gpole" type="capsule" fromto="0 0 0 0 0 1.0"  rgba="1 1 1 1" mass="1." size="0.1 0.5"/>
        <!--        massless endpoint sphere, position chosen according to length of pole-->
        <body name="mass" pos="0 0 1.0">
            <geom name="gmass" type="sphere" size="0.2 0.2" mass="0" rgba="1 1 1 1" contype="3" conaffinity="3"/>
            <!--            seemingly unused site-->
            <site name="tip" pos="0 0 0." size="0.01 0.01"/>
        </body>
      </body>
    </body>
<!--    <body name="target" pos="-0.75 0 -0.75">-->
<!--      <geom rgba="1 1 1 1" size="0.1 0.1" mass="1." type="sphere" name="gtarget" contype="2" conaffinity="2"/>-->
<!--    </body>-->
  </worldbody>
  <actuator>
    <motor joint="slider" name="slide" ctrllimited="true" ctrlrange="-1 1" gear="40"/>
  </actuator>
</mujoco>