<!-- Doublecartpole Model
    The state space is populated with joints in the order that they are
    defined in this file. The actuators also operate on joints.
    State-Space ([qpos, qvel]) (joint-name/joint-type/parameter-units):
        - xcart      slider      position (m)
        - hinge      hinge       angle (theta)
        - hinge2     hinge       angle (theta)
        - xcart      slider      vel (m/s)
        - hinge      hinge       angular vel (rad/s)
        - hinge2     hinge       angular vel (rad/s)
    Actuators (name/actuator/parameter):
        - cart      motor       force x (N)
-->
<mujoco model="double_cartpole">
  <compiler coordinate="local" inertiafromgeom="true"/>
  <!--  create defaults for joints in cartpole -->
  <default>
    <!-- larger damping values can make sim unstable-->
    <joint damping="0.1"/>
    <!--  two geoms can collide if the contype of one geom is compatible with the con-affinity of another geom and they
    have a common `1` in their 32b representations -->
    <!--    friction = (sliding, rolling, torsional)-->
    <geom contype="3" conaffinity="3" friction="0 0 0" rgba="0.7 0.7 0 1"/>
  </default>
  <!-- time step is physics time step, no separate control time-step -->
  <option gravity="1e-5 0 -9.81" integrator="Euler" timestep="0.05"/>
  <!--  initial size of allocated stack-->
  <size nstack="3000"/>
  <worldbody>
    <!-- Define a camera fixed relative to the static global world-body -->
    <camera name="rgb" mode="fixed" pos="0.0 -4 0.0" euler="90 0 0"/>
    <body name="cart" pos="0 0 0">
      <!--      the actuated joint which we call slider-->
      <!--      margin is distance below which contacts become active. Implements notion of "soft contact" -->
      <joint name="slider" axis="1 0 0" limited="true" margin="0.01" pos="0 0 0" range="-100 100" type="slide"/>
      <!--      small sized cart (alpha=0) with orientation chosen such that we look at the planar object head on -->
      <geom name="gcart" type="capsule" pos="0 0 0" quat="0.707 0 0.707 0 " rgba="1 1 1 0" size="0.01 0.01" mass="1."/>
      <body name="pole1" pos="0 0 0">
        <joint axis="0 1 0" name="hinge" pos="0 0 0" type="hinge" stiffness="0"/>
<!--        when fromto is used, size is just radius of hemi-sphere caps, and orientation is implicit in fromto-->
        <geom name="gpole1" type="capsule" fromto="0 0 0 0 0 0.5" rgba="1 1 1 1" size="0.1" mass="0.5" contype="2"/>
        <body name="pole2" pos="0 0 0.5">
<!--          Create a tiny site at the location of hinge2 to retreive its x and y coordinate later-->
          <site name="hinge2" pos="0 0 0." size="0.01 0.01"/>
          <joint axis="0 1 0" name="hinge2" pos="0 0 0" type="hinge"/>
          <geom name="gpole2" type="capsule" fromto="0 0 0 0 0 0.5" rgba="1 1 1 1" size="0.1" mass="0.5" contype="1"/>
           <body name="mass" pos="0 0 0.5">
            <geom name="gmass" type="sphere" size="0.2 0.2" mass="0" rgba="1 1 1 1" contype="3" conaffinity="3"/>
<!--            <site name="tip" pos="0 0 0." size="0.01 0.01"/>-->
           </body>
        </body>
      </body>
    </body>
  </worldbody>
  <actuator>
    <motor joint="slider" name="slide" ctrllimited="true" ctrlrange="-1 1" gear="40"/>
  </actuator>
</mujoco>
