<mujoco model="double_cartpole">
  <compiler coordinate="local" inertiafromgeom="true"/>
  <option timestep="0.05" gravity="1.0000000000000001e-05 0 -9.8100000000000005" integrator="Euler"/>
  <size nstack="3000"/>
  <default>
    <default class="/">
      <joint damping="0.1"/>
      <geom contype="3" conaffinity="3" rgba="0.69999999999999996 0.69999999999999996 0 1" friction="0 0 0"/>
    </default>
  </default>
  <worldbody>
    <camera name="rgb" class="/" mode="fixed" pos="0 -4 0" euler="90 0 0"/>
    <body name="cart" pos="0 0 0">
      <joint name="slider" class="/" type="slide" pos="0 0 0" axis="1 0 0" limited="true" range="-100 100" margin="0.01"/>
      <geom name="gcart" class="/" type="capsule" size="0.01 0.01" rgba="1 1 1 0" mass="1.0" pos="0 0 0" quat="0.70699999999999996 0 0.70699999999999996 0"/>
      <body name="pole1" pos="0 0 0">
        <joint name="hinge" class="/" type="hinge" pos="0 0 0" axis="0 1 0" stiffness="0.0"/>
        <geom name="gpole1" class="/" type="capsule" contype="2" size="0.12970488195809254" rgba="1 1 1 1" mass="0.5" fromto="0 0 0 0 0 0.42424996825379435"/>
        <body name="pole2" pos="0 0 0.42424996825379435">
          <site name="hinge2" class="/" size="0.01 0.01" pos="0 0 0"/>
          <joint name="hinge2" class="/" type="hinge" pos="0 0 0" axis="0 1 0"/>
          <geom name="gpole2" class="/" type="capsule" contype="1" size="0.12970488195809254" rgba="1 1 1 1" mass="0.5" fromto="0 0 0 0 0 0.60492950469529572"/>
          <body name="mass" pos="0 0 0.60492950469529572">
            <geom name="gmass" class="/" type="sphere" contype="3" conaffinity="3" size="0.19910082267355123 0.19910082267355123" rgba="1 1 1 1" mass="0.0"/>
          </body>
        </body>
      </body>
    </body>
  </worldbody>
  <actuator>
    <motor name="slide" class="/" ctrllimited="true" ctrlrange="-1 1" gear="40" joint="slider"/>
  </actuator>
</mujoco>
