<mujoco model="kendama">
  <compiler coordinate="local" inertiafromgeom="true"/>
  <default>
    <joint damping="0.05" stiffness="0.1"/>
    <geom contype="3" conaffinity="3" friction="1 0.1 0.1" rgba="0.7 0.7 0 1"/>
  </default>
  <option gravity="1e-5 0 -9.81" integrator="RK4" timestep="0.001"/>
  <size nstack="3000"/>
  <worldbody>
    <camera name="rgb" mode="fixed" pos="0 4 0.0" euler="-90 0 180"/>
    <body name="cup" pos="0 0 0">
      <joint axis="1 0 0" limited="true" margin="0.01" name="slider" pos="0 0 0" range="-20 20" stiffness="0" type="slide"/>
      <!-- cup environment is similar to conkers environment but with the geom of a cup replacing cart -->
      <geom name="cup" pos="0 0 0" quat="0.707 0 0.707 0" size="0.1 0.1" rgba="1 1 1 1" type="capsule" mass=".5"/>
      <body name="pole" pos="0 0 0">
        <joint axis="0 1 0" name="hinge" pos="0 0 0" type="hinge" stiffness="0"/>
        <geom fromto="0 0 0 0 0 0.1" name="gpole1" rgba="1 1 1 1" size="0.1 0.05" mass="0.05" type="capsule"/>
        <body name="pole2" pos="0 0 0.1">
          <joint axis="0 1 0" name="hinge2" pos="0 0 0" type="hinge"/>
          <geom fromto="0 0 0 0 0 0.1" name="gpole2" rgba="1 1 1 1" size="0.1 0.05" mass="0.05" type="capsule"/>
          <body name="pole3" pos="0 0 0.1">
            <joint axis="0 1 0" name="hinge3" pos="0 0 0" type="hinge"/>
            <geom fromto="0 0 0 0 0 0.1" name="gpole3" rgba="1 1 1 1" size="0.1 0.05" mass="0.05" type="capsule"/>
            <body name="pole4" pos="0 0 0.1">
              <joint axis="0 1 0" name="hinge4" pos="0 0 0" type="hinge"/>
              <geom fromto="0 0 0 0 0 0.1" name="gpole4" rgba="1 1 1 1" size="0.1 0.05" mass="0.05" type="capsule"/>
               <body name="pole5" pos="0 0 0.1">
              <joint axis="0 1 0" name="hinge5" pos="0 0 0" type="hinge"/>
              <geom fromto="0 0 0 0 0 0.1" name="gpole5" rgba="1 1 1 1" size="0.1 0.05" mass="0.05" type="capsule"/>
                 <body name="pole6" pos="0 0 0.1">
                   <joint axis="0 1 0" name="hinge6" pos="0 0 0" type="hinge"/>
                   <geom fromto="0 0 0 0 0 0.1" name="gpole6" rgba="1 1 1 1" size="0.1 0.05" mass="0.05" type="capsule"/>
                     <body name="pole7" pos="0 0 0.1">
                      <joint axis="0 1 0" name="hinge7" pos="0 0 0" type="hinge"/>
                      <geom fromto="0 0 0 0 0 0.1" name="gpole7" rgba="1 1 1 1" size="0.1 0.05" mass="0.05" type="capsule"/>
                        <body name="pole8" pos="0 0 0.1">
                        <joint axis="0 1 0" name="hinge8" pos="0 0 0" type="hinge"/>
                        <geom fromto="0 0 0 0 0 0.1" name="gpole8" rgba="1 1 1 1" size="0.1 0.05" mass="0.05" type="capsule"/>
                        <body name="pole9" pos="0 0 0.1">
                          <joint axis="0 1 0" name="hinge9" pos="0 0 0" type="hinge"/>
                          <geom fromto="0 0 0 0 0 0.1" name="gpole9" rgba="1 1 1 1" size="0.1 0.05" mass="0.05" type="capsule"/>
                            <body name="pole10" pos="0 0 0.1">
                              <joint axis="0 1 0" name="hinge10" pos="0 0 0" type="hinge"/>
                              <geom fromto="0 0 0 0 0 0.1" name="gpole10" rgba="1 1 1 1" size="0.1 0.05" mass="0.05" type="capsule"/>
                              <body name="conker" pos="0 0 0.1">
                                <geom type="sphere" rgba="1 1 1 1" mass="1." size="0.2 0.2" name="gmass" contype="3" conaffinity="3"/>
                                <site name="tip" pos="0 0 0." size="0.01 0.01"/>
                              </body>
                            </body>
                          </body>
                        </body>
                      </body>
                      </body>
                    </body>
                  </body>
                </body>
            </body>
          </body>
        </body>
    <body name="target" pos="-0.75 0 -0.75">
      <geom rgba="0 0 0 0" size="0.1 0.1" mass="1." type="sphere" name="gtarget" conaffinity="2" contype="2"/>
    </body>
  </worldbody>
  <actuator>
    <motor ctrllimited="true" ctrlrange="-1 1" gear="40" joint="slider" name="slide"/>
  </actuator>
</mujoco>